INFO: 2024-03-11 18:58:36,591: main() 'Using profile folder /home/wste/.config/variety/'
INFO: 2024-03-11 18:58:36,596: perform_upgrade() 'Last run version was 0.8.12 or earlier, current version is 0.8.12'
INFO: 2024-03-11 18:58:36,995: process_command() 'Received command: ['--profile', '/home/wste/.config/variety/']'
INFO: 2024-03-11 18:58:37,006: start() 'Using data_path /usr/share/variety'
INFO: 2024-03-11 18:58:37,007: load() 'Jumble loading'
INFO: 2024-03-11 18:58:37,008: _walk_modules() 'Jumble loading module in __init__ from /usr/lib/python3.11/site-packages/variety/plugins/builtin/__init__.py'
INFO: 2024-03-11 18:58:37,010: _walk_modules() 'Jumble loading module in LocalFilesSource from /usr/lib/python3.11/site-packages/variety/plugins/builtin/quotes/LocalFilesSource.py'
INFO: 2024-03-11 18:58:37,013: load() 'Jumble found plugin class: <class 'LocalFilesSource.LocalFilesSource'>: {'name': 'Local text files', 'description': 'Displays quotes, defined in local text files.\nPut your own txt files in: /home/wste/.config/variety/pluginconfig/quotes/.\nThe file format is:\n\nquote -- author\n.\nsecond quote -- another author\n.\netc...\n\nExample: http://rvelthuis.de/zips/quotes.txt', 'author': 'Peter Levi', 'version': '0.1'}'
INFO: 2024-03-11 18:58:37,013: _walk_modules() 'Jumble loading module in FortuneSource from /usr/lib/python3.11/site-packages/variety/plugins/builtin/quotes/FortuneSource.py'
INFO: 2024-03-11 18:58:37,016: load() 'Jumble found plugin class: <class 'FortuneSource.FortuneSource'>: {'name': 'UNIX fortune program', 'description': 'Displays quotes using the UNIX fortune program. You may want to install additional fortune packs, e.g. fortunes-bofh-excuses.', 'author': 'Dan Jones', 'version': '0.1'}'
INFO: 2024-03-11 18:58:37,017: _walk_modules() 'Jumble loading module in GoodreadsSource from /usr/lib/python3.11/site-packages/variety/plugins/builtin/quotes/GoodreadsSource.py'
INFO: 2024-03-11 18:58:37,129: load() 'Jumble found plugin class: <class 'GoodreadsSource.GoodreadsSource'>: {'name': 'Goodreads', 'description': 'Fetches quotes from Goodreads.com', 'author': 'Peter Levi', 'version': '0.1'}'
INFO: 2024-03-11 18:58:37,129: _walk_modules() 'Jumble loading module in QuotationsPageSource from /usr/lib/python3.11/site-packages/variety/plugins/builtin/quotes/QuotationsPageSource.py'
INFO: 2024-03-11 18:58:37,131: load() 'Jumble found plugin class: <class 'QuotationsPageSource.QuotationsPageSource'>: {'name': 'TheQuotationsPage.com', 'description': 'Fetches quotes from TheQuotationsPage.com', 'author': 'Peter Levi', 'version': '0.1'}'
INFO: 2024-03-11 18:58:37,131: _walk_modules() 'Jumble loading module in __init__ from /usr/lib/python3.11/site-packages/variety/plugins/builtin/quotes/__init__.py'
INFO: 2024-03-11 18:58:37,131: _walk_modules() 'Jumble loading module in UrbanDictionarySource from /usr/lib/python3.11/site-packages/variety/plugins/builtin/quotes/UrbanDictionarySource.py'
INFO: 2024-03-11 18:58:37,132: load() 'Jumble found plugin class: <class 'UrbanDictionarySource.UrbanDictionarySource'>: {'name': 'Urban Dictionary', 'description': 'Displays definitions from Urban Dictionary', 'author': 'James Miller', 'version': '0.1'}'
INFO: 2024-03-11 18:58:37,133: _walk_modules() 'Jumble loading module in LegacyDisplayModesPlugin from /usr/lib/python3.11/site-packages/variety/plugins/builtin/display_modes/LegacyDisplayModesPlugin.py'
INFO: 2024-03-11 18:58:37,134: load() 'Jumble found plugin class: <class 'LegacyDisplayModesPlugin.LegacyDisplayModesPlugin'>: {'name': 'LegacyDisplayModesPlugin', 'description': 'Legacy display mode for compatibility with past Variety versions', 'version': '1.0', 'author': 'Peter Levi'}'
INFO: 2024-03-11 18:58:37,135: _walk_modules() 'Jumble loading module in GnomeDisplayModesPlugin from /usr/lib/python3.11/site-packages/variety/plugins/builtin/display_modes/GnomeDisplayModesPlugin.py'
INFO: 2024-03-11 18:58:37,136: load() 'Jumble found plugin class: <class 'GnomeDisplayModesPlugin.GnomeDisplayModesPlugin'>: {'name': 'GnomeDisplayModesPlugin', 'description': 'Display modes relying on the underlying desktop environment', 'version': '1.0', 'author': 'Peter Levi'}'
INFO: 2024-03-11 18:58:37,136: _walk_modules() 'Jumble loading module in __init__ from /usr/lib/python3.11/site-packages/variety/plugins/builtin/display_modes/__init__.py'
INFO: 2024-03-11 18:58:37,137: _walk_modules() 'Jumble loading module in ResizingDisplayModesPlugin from /usr/lib/python3.11/site-packages/variety/plugins/builtin/display_modes/ResizingDisplayModesPlugin.py'
INFO: 2024-03-11 18:58:37,138: load() 'Jumble found plugin class: <class 'ResizingDisplayModesPlugin.ResizingDisplayModesPlugin'>: {'name': 'ResizingDisplayModesPlugin', 'description': 'Display modes that use image resizing within Variety', 'version': '1.0', 'author': 'Peter Levi'}'
INFO: 2024-03-11 18:58:37,139: _walk_modules() 'Jumble loading module in WallhavenSource from /usr/lib/python3.11/site-packages/variety/plugins/builtin/downloaders/WallhavenSource.py'
INFO: 2024-03-11 18:58:37,146: load() 'Jumble found plugin class: <class 'WallhavenSource.WallhavenSource'>: {'name': 'WallhavenSource', 'description': 'Configurable source for fetching images from Wallhaven.cc', 'author': 'Peter Levi', 'version': '0.1'}'
INFO: 2024-03-11 18:58:37,146: _walk_modules() 'Jumble loading module in UnsplashConfigurableSource from /usr/lib/python3.11/site-packages/variety/plugins/builtin/downloaders/UnsplashConfigurableSource.py'
INFO: 2024-03-11 18:58:37,149: load() 'Jumble found plugin class: <class 'UnsplashConfigurableSource.UnsplashConfigurableSource'>: {'name': 'UnsplashConfigurableSource', 'description': 'Configurable source for fetching photos from Unsplash.com', 'author': 'Peter Levi', 'version': '0.1'}'
INFO: 2024-03-11 18:58:37,150: _walk_modules() 'Jumble loading module in ArtStationSource from /usr/lib/python3.11/site-packages/variety/plugins/builtin/downloaders/ArtStationSource.py'
INFO: 2024-03-11 18:58:37,152: load() 'Jumble found plugin class: <class 'ArtStationSource.ArtStationSource'>: {'name': 'ArtStationSource', 'description': 'Configurable source for fetching images from ArtStation', 'author': 'Denis Gordeev', 'version': '0.1'}'
INFO: 2024-03-11 18:58:37,152: _walk_modules() 'Jumble loading module in RedditDownloader from /usr/lib/python3.11/site-packages/variety/plugins/builtin/downloaders/RedditDownloader.py'
INFO: 2024-03-11 18:58:37,154: _walk_modules() 'Jumble loading module in NationalGeographicDownloader from /usr/lib/python3.11/site-packages/variety/plugins/builtin/downloaders/NationalGeographicDownloader.py'
INFO: 2024-03-11 18:58:37,155: load() 'Jumble found plugin class: <class 'NationalGeographicDownloader.NationalGeographicDownloader'>: {'name': 'NationalGeographicDownloader', 'description': "National Geographic's photo of the day", 'author': 'Eric RÃ¶sch', 'version': '0.1'}'
INFO: 2024-03-11 18:58:37,156: _walk_modules() 'Jumble loading module in RedditSource from /usr/lib/python3.11/site-packages/variety/plugins/builtin/downloaders/RedditSource.py'
INFO: 2024-03-11 18:58:37,158: load() 'Jumble found plugin class: <class 'RedditSource.RedditSource'>: {'name': 'RedditSource', 'description': 'Configurable source for fetching images from Reddit', 'author': 'Peter Levi', 'version': '0.1'}'
INFO: 2024-03-11 18:58:37,158: _walk_modules() 'Jumble loading module in WallhavenLegacyDownloader from /usr/lib/python3.11/site-packages/variety/plugins/builtin/downloaders/WallhavenLegacyDownloader.py'
INFO: 2024-03-11 18:58:37,159: _walk_modules() 'Jumble loading module in EarthviewDownloader from /usr/lib/python3.11/site-packages/variety/plugins/builtin/downloaders/EarthviewDownloader.py'
INFO: 2024-03-11 18:58:37,160: load() 'Jumble found plugin class: <class 'EarthviewDownloader.EarthviewDownloader'>: {'name': 'EarthviewDownloader', 'description': 'Google Earth View Wallpapers', 'author': 'Peter Levi', 'version': '0.1'}'
INFO: 2024-03-11 18:58:37,161: _walk_modules() 'Jumble loading module in WallhavenDownloader from /usr/lib/python3.11/site-packages/variety/plugins/builtin/downloaders/WallhavenDownloader.py'
INFO: 2024-03-11 18:58:37,162: _walk_modules() 'Jumble loading module in BingDownloader from /usr/lib/python3.11/site-packages/variety/plugins/builtin/downloaders/BingDownloader.py'
INFO: 2024-03-11 18:58:37,164: load() 'Jumble found plugin class: <class 'BingDownloader.BingDownloader'>: {'name': 'BingDownloader', 'description': 'Bing Photo of the Day', 'author': 'Peter Levi', 'version': '0.1'}'
INFO: 2024-03-11 18:58:37,164: _walk_modules() 'Jumble loading module in UnsplashDownloader from /usr/lib/python3.11/site-packages/variety/plugins/builtin/downloaders/UnsplashDownloader.py'
INFO: 2024-03-11 18:58:37,165: load() 'Jumble found plugin class: <class 'UnsplashDownloader.UnsplashDownloader'>: {'name': 'UnsplashDownloader', 'description': 'High-resolution photos from Unsplash.com', 'author': 'Peter Levi', 'version': '0.1'}'
INFO: 2024-03-11 18:58:37,165: _walk_modules() 'Jumble loading module in APODDownloader from /usr/lib/python3.11/site-packages/variety/plugins/builtin/downloaders/APODDownloader.py'
INFO: 2024-03-11 18:58:37,166: load() 'Jumble found plugin class: <class 'APODDownloader.APODDownloader'>: {'name': 'APODDownloader', 'description': 'NASA Astro Pic of the Day', 'author': 'Peter Levi', 'version': '0.1'}'
INFO: 2024-03-11 18:58:37,167: _walk_modules() 'Jumble loading module in MediaRSSDownloader from /usr/lib/python3.11/site-packages/variety/plugins/builtin/downloaders/MediaRSSDownloader.py'
INFO: 2024-03-11 18:58:37,168: _walk_modules() 'Jumble loading module in ArtStationDownloader from /usr/lib/python3.11/site-packages/variety/plugins/builtin/downloaders/ArtStationDownloader.py'
INFO: 2024-03-11 18:58:37,170: _walk_modules() 'Jumble loading module in __init__ from /usr/lib/python3.11/site-packages/variety/plugins/builtin/downloaders/__init__.py'
INFO: 2024-03-11 18:58:37,170: _walk_modules() 'Jumble loading module in MediaRSSSource from /usr/lib/python3.11/site-packages/variety/plugins/builtin/downloaders/MediaRSSSource.py'
INFO: 2024-03-11 18:58:37,172: load() 'Jumble found plugin class: <class 'MediaRSSSource.MediaRSSSource'>: {'name': 'MediaRSSSource', 'description': 'Configurable source for fetching images from MediaRSS feeds', 'author': 'Peter Levi', 'version': '0.1'}'
INFO: 2024-03-11 18:58:37,204: reload_config() 'Creating new downloader for type flickr, location user:www.flickr.com/photos/peter-levi/;user_id:93647178@N00;'
INFO: 2024-03-11 18:58:37,205: log_options() 'Loaded options:'
INFO: 2024-03-11 18:58:37,205: log_options() 'change_enabled = True'
INFO: 2024-03-11 18:58:37,205: log_options() 'change_interval = 300'
INFO: 2024-03-11 18:58:37,206: log_options() 'change_on_start = False'
INFO: 2024-03-11 18:58:37,206: log_options() 'clipboard_enabled = False'
INFO: 2024-03-11 18:58:37,206: log_options() 'clipboard_hosts = ['wallhaven.cc', 'wallpapers.net', 'flickr.com', 'imgur.com', 'deviantart.com', 'interfacelift.com', 'vladstudio.com', 'imageshack.us', 'deviantart.net', 'imageshack.com']'
INFO: 2024-03-11 18:58:37,206: log_options() 'clipboard_use_whitelist = True'
INFO: 2024-03-11 18:58:37,206: log_options() 'clock_date_font = Serif 30'
INFO: 2024-03-11 18:58:37,206: log_options() 'clock_enabled = False'
INFO: 2024-03-11 18:58:37,206: log_options() 'clock_filter = -density 100 -font `fc-match -f '%{file[0]}' '%CLOCK_FONT_NAME'` -pointsize %CLOCK_FONT_SIZE -gravity SouthEast -fill '#00000044' -annotate 0x0+[%HOFFSET+58]+[%VOFFSET+108] '%H:%M' -fill white -annotate 0x0+[%HOFFSET+60]+[%VOFFSET+110] '%H:%M' -font `fc-match -f '%{file[0]}' '%DATE_FONT_NAME'` -pointsize %DATE_FONT_SIZE -fill '#00000044' -annotate 0x0+[%HOFFSET+58]+[%VOFFSET+58] '%A, %B %d' -fill white -annotate 0x0+[%HOFFSET+60]+[%VOFFSET+60] '%A, %B %d''
INFO: 2024-03-11 18:58:37,206: log_options() 'clock_font = Serif 70'
INFO: 2024-03-11 18:58:37,206: log_options() 'configfile = /home/wste/.config/variety/variety.conf'
INFO: 2024-03-11 18:58:37,206: log_options() 'copyto_enabled = False'
INFO: 2024-03-11 18:58:37,206: log_options() 'copyto_folder = Default'
INFO: 2024-03-11 18:58:37,206: log_options() 'desired_color = [160, 160, 160]'
INFO: 2024-03-11 18:58:37,206: log_options() 'desired_color_enabled = False'
INFO: 2024-03-11 18:58:37,206: log_options() 'download_folder = /home/wste/.config/variety/Downloaded'
INFO: 2024-03-11 18:58:37,206: log_options() 'download_preference_ratio = 0.9'
INFO: 2024-03-11 18:58:37,206: log_options() 'favorites_folder = /home/wste/.config/variety/Favorites'
INFO: 2024-03-11 18:58:37,206: log_options() 'favorites_operations = [['Downloaded', 'Copy'], ['Fetched', 'Move'], ['Others', 'Copy']]'
INFO: 2024-03-11 18:58:37,206: log_options() 'fetched_folder = /home/wste/.config/variety/Fetched'
INFO: 2024-03-11 18:58:37,206: log_options() 'filters = [[False, 'Keep original', ''], [False, 'Grayscale', '-type Grayscale'], [False, 'Heavy blur', '-scale 20% -blur 0x10 -resize 500%'], [False, 'Soft blur', '-scale 20% -blur 0x2 -resize 500%'], [False, 'Oil painting', '-paint 8'], [False, 'Pointilism', '-spread 10 -noise 3'], [False, 'Pixellate', '-scale 3% -scale 3333%']]'
INFO: 2024-03-11 18:58:37,206: log_options() 'get_wallpaper_script = /home/wste/.config/variety/scripts/get_wallpaper'
INFO: 2024-03-11 18:58:37,207: log_options() 'icon = Light'
INFO: 2024-03-11 18:58:37,207: log_options() 'internet_enabled = True'
INFO: 2024-03-11 18:58:37,207: log_options() 'lightness_enabled = False'
INFO: 2024-03-11 18:58:37,207: log_options() 'lightness_mode = 0'
INFO: 2024-03-11 18:58:37,207: log_options() 'min_rating = 4'
INFO: 2024-03-11 18:58:37,207: log_options() 'min_rating_enabled = False'
INFO: 2024-03-11 18:58:37,207: log_options() 'min_size = 80'
INFO: 2024-03-11 18:58:37,207: log_options() 'min_size_enabled = False'
INFO: 2024-03-11 18:58:37,207: log_options() 'quota_enabled = True'
INFO: 2024-03-11 18:58:37,207: log_options() 'quota_size = 1000'
INFO: 2024-03-11 18:58:37,207: log_options() 'quotes_authors = '
INFO: 2024-03-11 18:58:37,207: log_options() 'quotes_bg_color = [80, 80, 80]'
INFO: 2024-03-11 18:58:37,207: log_options() 'quotes_bg_opacity = 55'
INFO: 2024-03-11 18:58:37,207: log_options() 'quotes_change_enabled = False'
INFO: 2024-03-11 18:58:37,207: log_options() 'quotes_change_interval = 300'
INFO: 2024-03-11 18:58:37,207: log_options() 'quotes_disabled_sources = ['Urban Dictionary']'
INFO: 2024-03-11 18:58:37,207: log_options() 'quotes_enabled = False'
INFO: 2024-03-11 18:58:37,207: log_options() 'quotes_favorites_file = /home/wste/.config/variety/favorite_quotes.txt'
INFO: 2024-03-11 18:58:37,207: log_options() 'quotes_font = Serif 30'
INFO: 2024-03-11 18:58:37,207: log_options() 'quotes_hpos = 100'
INFO: 2024-03-11 18:58:37,207: log_options() 'quotes_max_length = 250'
INFO: 2024-03-11 18:58:37,207: log_options() 'quotes_tags = '
INFO: 2024-03-11 18:58:37,207: log_options() 'quotes_text_color = [255, 255, 255]'
INFO: 2024-03-11 18:58:37,207: log_options() 'quotes_text_shadow = False'
INFO: 2024-03-11 18:58:37,208: log_options() 'quotes_vpos = 40'
INFO: 2024-03-11 18:58:37,208: log_options() 'quotes_width = 70'
INFO: 2024-03-11 18:58:37,208: log_options() 'safe_mode = False'
INFO: 2024-03-11 18:58:37,208: log_options() 'set_wallpaper_script = /home/wste/.config/variety/scripts/set_wallpaper'
INFO: 2024-03-11 18:58:37,208: log_options() 'slideshow_custom_enabled = False'
INFO: 2024-03-11 18:58:37,208: log_options() 'slideshow_custom_folder = /home/wste/Pictures'
INFO: 2024-03-11 18:58:37,208: log_options() 'slideshow_downloads_enabled = False'
INFO: 2024-03-11 18:58:37,208: log_options() 'slideshow_fade = 0.4'
INFO: 2024-03-11 18:58:37,208: log_options() 'slideshow_favorites_enabled = True'
INFO: 2024-03-11 18:58:37,208: log_options() 'slideshow_mode = Fullscreen'
INFO: 2024-03-11 18:58:37,208: log_options() 'slideshow_monitor = All'
INFO: 2024-03-11 18:58:37,208: log_options() 'slideshow_pan = 0.05'
INFO: 2024-03-11 18:58:37,208: log_options() 'slideshow_seconds = 6.0'
INFO: 2024-03-11 18:58:37,208: log_options() 'slideshow_sort_order = Random'
INFO: 2024-03-11 18:58:37,208: log_options() 'slideshow_sources_enabled = True'
INFO: 2024-03-11 18:58:37,208: log_options() 'slideshow_zoom = 0.2'
INFO: 2024-03-11 18:58:37,208: log_options() 'smart_enabled = False'
INFO: 2024-03-11 18:58:37,208: log_options() 'smart_notice_shown = False'
INFO: 2024-03-11 18:58:37,208: log_options() 'smart_register_shown = False'
INFO: 2024-03-11 18:58:37,208: log_options() 'sources = [[True, 'favorites', 'The Favorites folder'], [True, 'fetched', 'The Fetched folder'], [True, 'folder', '/usr/share/backgrounds'], [True, 'flickr', 'user:www.flickr.com/photos/peter-levi/;user_id:93647178@N00;'], [False, 'apod', "NASA's Astronomy Picture of the Day"], [False, 'bing', 'Bing Photo of the Day'], [False, 'earthview', 'Google Earth View Wallpapers'], [False, 'natgeo', "National Geographic's photo of the day"], [False, 'unsplash', 'High-resolution photos from Unsplash.com']]'
INFO: 2024-03-11 18:58:37,208: log_options() 'stats_enabled = True'
INFO: 2024-03-11 18:58:37,208: log_options() 'stats_notice_shown = False'
INFO: 2024-03-11 18:58:37,208: log_options() 'sync_enabled = True'
INFO: 2024-03-11 18:58:37,209: log_options() 'use_landscape_enabled = True'
INFO: 2024-03-11 18:58:37,209: log_options() 'wallhaven_api_key = '
INFO: 2024-03-11 18:58:37,209: log_options() 'wallpaper_auto_rotate = False'
INFO: 2024-03-11 18:58:37,209: log_options() 'wallpaper_display_mode = os'
INFO: 2024-03-11 18:58:37,209: reload_config() 'No need to clear prepared queue'
INFO: 2024-03-11 18:58:37,209: update_indicator() 'Setting file info to: /usr/share/backgrounds/gnome/adwaita-l.jpg'
INFO: 2024-03-11 18:58:37,213: load_banned() 'Missing or invalid banned URLs list, no URLs will be banned'
INFO: 2024-03-11 18:58:37,213: load_last_change_time() 'Change interval < 6 hours, ignore persisted last_change_time, wait initially the whole interval: 300'
INFO: 2024-03-11 18:58:37,213: update_indicator() 'Setting file info to: /usr/share/backgrounds/gnome/adwaita-l.jpg'
INFO: 2024-03-11 18:58:37,214: regular_change_thread() 'regular_change thread running'
INFO: 2024-03-11 18:58:37,214: prepare_thread() 'Prepare thread running'
INFO: 2024-03-11 18:58:37,215: prepare_thread() 'Prepared buffer contains 0 images'
INFO: 2024-03-11 18:58:37,215: prepare_thread() 'Preparing some images'
INFO: 2024-03-11 18:58:37,215: get_throttling() 'Flickr: parsing serverside options'
INFO: 2024-03-11 18:58:37,215: get_throttling() 'Could not parse Flickr serverside options, using defaults 120, 20'
INFO: 2024-03-11 18:58:37,215: get_throttling() 'Flickr: parsing serverside options'
INFO: 2024-03-11 18:58:37,215: get_throttling() 'Could not parse Flickr serverside options, using defaults 120, 20'
INFO: 2024-03-11 18:58:37,216: download_one() 'Flickr: Downloading an image, config: user:www.flickr.com/photos/peter-levi/;user_id:93647178@N00;'
INFO: 2024-03-11 18:58:37,216: download_one() 'Flickr: Queue size: 0'
INFO: 2024-03-11 18:58:37,216: get_throttling() 'Flickr: parsing serverside options'
INFO: 2024-03-11 18:58:37,216: get_throttling() 'Could not parse Flickr serverside options, using defaults 120, 20'
INFO: 2024-03-11 18:58:37,216: download_one() 'Flickr: Filling queue'
INFO: 2024-03-11 18:58:37,216: fetch() 'Making flickr API call: https://api.flickr.com/services/rest/?method=flickr.photos.search&api_key=0553a848c09bcfd21d3a984d9408c04e&per_page=500&tag_mode=all&format=json&nojsoncallback=1&user_id=93647178@N00'
INFO: 2024-03-11 18:58:37,219: update_indicator_icon() 'Creating indicator'
INFO: 2024-03-11 18:58:37,315: do_set_wp() 'Calling do_set_wp with /usr/share/backgrounds/gnome/adwaita-l.jpg, time: 1710154717.3157868'
INFO: 2024-03-11 18:58:37,316: do_set_wp() 'Missing file or bad permissions, will not use it: /usr/share/backgrounds/gnome/adwaita-l.jpg'
INFO: 2024-03-11 18:58:37,331: prepare_thread() 'After search prepared buffer contains 5 images'
WARNING: 2024-03-11 18:58:37,339: create_menu() 'Variety Slideshow is not installed. This is an optional extension adding pan-and-zoom slideshows to Variety: see https://github.com/peterlevi/variety-slideshow for details'
INFO: 2024-03-11 18:58:37,341: create_indicator() 'indicator backend: AyatanaAppIndicator3'
INFO: 2024-03-11 18:58:37,375: set_from_theme_icon() 'Showing indicator icon variety-indicator from GTK theme'
INFO: 2024-03-11 18:58:38,867: reload() 'Reloading preferences dialog'
INFO: 2024-03-11 18:58:39,332: trigger_download() 'Triggering download thread to check if download needed and possible'
ERROR: 2024-03-11 18:58:42,367: download_one_from() 'Could not download wallpaper:'
Traceback (most recent call last):
  File "/usr/lib/python3.11/site-packages/urllib3/connectionpool.py", line 404, in _make_request
    self._validate_conn(conn)
  File "/usr/lib/python3.11/site-packages/urllib3/connectionpool.py", line 1058, in _validate_conn
    conn.connect()
  File "/usr/lib/python3.11/site-packages/urllib3/connection.py", line 419, in connect
    self.sock = ssl_wrap_socket(
                ^^^^^^^^^^^^^^^^
  File "/usr/lib/python3.11/site-packages/urllib3/util/ssl_.py", line 449, in ssl_wrap_socket
    ssl_sock = _ssl_wrap_socket_impl(
               ^^^^^^^^^^^^^^^^^^^^^^
  File "/usr/lib/python3.11/site-packages/urllib3/util/ssl_.py", line 493, in _ssl_wrap_socket_impl
    return ssl_context.wrap_socket(sock, server_hostname=server_hostname)
           ^^^^^^^^^^^^^^^^^^^^^^^^^^^^^^^^^^^^^^^^^^^^^^^^^^^^^^^^^^^^^^
  File "/usr/lib/python3.11/ssl.py", line 517, in wrap_socket
    return self.sslsocket_class._create(
           ^^^^^^^^^^^^^^^^^^^^^^^^^^^^^
  File "/usr/lib/python3.11/ssl.py", line 1104, in _create
    self.do_handshake()
  File "/usr/lib/python3.11/ssl.py", line 1382, in do_handshake
    self._sslobj.do_handshake()
TimeoutError: _ssl.c:989: The handshake operation timed out

During handling of the above exception, another exception occurred:

Traceback (most recent call last):
  File "/usr/lib/python3.11/site-packages/requests/adapters.py", line 486, in send
    resp = conn.urlopen(
           ^^^^^^^^^^^^^
  File "/usr/lib/python3.11/site-packages/urllib3/connectionpool.py", line 799, in urlopen
    retries = retries.increment(
              ^^^^^^^^^^^^^^^^^^
  File "/usr/lib/python3.11/site-packages/urllib3/util/retry.py", line 550, in increment
    raise six.reraise(type(error), error, _stacktrace)
          ^^^^^^^^^^^^^^^^^^^^^^^^^^^^^^^^^^^^^^^^^^^^
  File "/usr/lib/python3.11/site-packages/urllib3/packages/six.py", line 770, in reraise
    raise value
  File "/usr/lib/python3.11/site-packages/urllib3/connectionpool.py", line 715, in urlopen
    httplib_response = self._make_request(
                       ^^^^^^^^^^^^^^^^^^^
  File "/usr/lib/python3.11/site-packages/urllib3/connectionpool.py", line 407, in _make_request
    self._raise_timeout(err=e, url=url, timeout_value=conn.timeout)
  File "/usr/lib/python3.11/site-packages/urllib3/connectionpool.py", line 358, in _raise_timeout
    raise ReadTimeoutError(
urllib3.exceptions.ReadTimeoutError: HTTPSConnectionPool(host='api.flickr.com', port=443): Read timed out. (read timeout=5)

During handling of the above exception, another exception occurred:

Traceback (most recent call last):
  File "/usr/lib/python3.11/site-packages/variety/VarietyWindow.py", line 1164, in download_one_from
    file = downloader.download_one()
           ^^^^^^^^^^^^^^^^^^^^^^^^^
  File "/usr/lib/python3.11/site-packages/variety/plugins/downloaders/DefaultDownloader.py", line 141, in download_one
    items = self.fill_queue()
            ^^^^^^^^^^^^^^^^^
  File "/usr/lib/python3.11/site-packages/variety/FlickrDownloader.py", line 161, in fill_queue
    resp = FlickrDownloader.fetch(call)
           ^^^^^^^^^^^^^^^^^^^^^^^^^^^^
  File "/usr/lib/python3.11/site-packages/variety/FlickrDownloader.py", line 74, in fetch
    return Util.fetch_json(call)
           ^^^^^^^^^^^^^^^^^^^^^
  File "/usr/lib/python3.11/site-packages/variety/Util.py", line 684, in fetch_json
    return Util.request(url, data, **request_kwargs).json()
           ^^^^^^^^^^^^^^^^^^^^^^^^^^^^^^^^^^^^^^^^^
  File "/usr/lib/python3.11/site-packages/variety/Util.py", line 654, in request
    r = requests.request(
        ^^^^^^^^^^^^^^^^^
  File "/usr/lib/python3.11/site-packages/requests/api.py", line 59, in request
    return session.request(method=method, url=url, **kwargs)
           ^^^^^^^^^^^^^^^^^^^^^^^^^^^^^^^^^^^^^^^^^^^^^^^^^
  File "/usr/lib/python3.11/site-packages/requests/sessions.py", line 589, in request
    resp = self.send(prep, **send_kwargs)
           ^^^^^^^^^^^^^^^^^^^^^^^^^^^^^^
  File "/usr/lib/python3.11/site-packages/requests/sessions.py", line 703, in send
    r = adapter.send(request, **kwargs)
        ^^^^^^^^^^^^^^^^^^^^^^^^^^^^^^^
  File "/usr/lib/python3.11/site-packages/requests/adapters.py", line 532, in send
    raise ReadTimeout(e, request=request)
requests.exceptions.ReadTimeout: HTTPSConnectionPool(host='api.flickr.com', port=443): Read timed out. (read timeout=5)
INFO: 2024-03-11 18:58:57,217: server_options_thread() 'Fetching server options from http://tiny.cc/variety-options-063'
ERROR: 2024-03-11 18:59:02,237: server_options_thread() 'Could not fetch Variety serverside options'
Traceback (most recent call last):
  File "/usr/lib/python3.11/site-packages/urllib3/connection.py", line 174, in _new_conn
    conn = connection.create_connection(
           ^^^^^^^^^^^^^^^^^^^^^^^^^^^^^
  File "/usr/lib/python3.11/site-packages/urllib3/util/connection.py", line 95, in create_connection
    raise err
  File "/usr/lib/python3.11/site-packages/urllib3/util/connection.py", line 85, in create_connection
    sock.connect(sa)
OSError: [Errno 101] Network is unreachable

During handling of the above exception, another exception occurred:

Traceback (most recent call last):
  File "/usr/lib/python3.11/site-packages/urllib3/connectionpool.py", line 715, in urlopen
    httplib_response = self._make_request(
                       ^^^^^^^^^^^^^^^^^^^
  File "/usr/lib/python3.11/site-packages/urllib3/connectionpool.py", line 416, in _make_request
    conn.request(method, url, **httplib_request_kw)
  File "/usr/lib/python3.11/site-packages/urllib3/connection.py", line 244, in request
    super(HTTPConnection, self).request(method, url, body=body, headers=headers)
  File "/usr/lib/python3.11/http/client.py", line 1298, in request
    self._send_request(method, url, body, headers, encode_chunked)
  File "/usr/lib/python3.11/http/client.py", line 1344, in _send_request
    self.endheaders(body, encode_chunked=encode_chunked)
  File "/usr/lib/python3.11/http/client.py", line 1293, in endheaders
    self._send_output(message_body, encode_chunked=encode_chunked)
  File "/usr/lib/python3.11/http/client.py", line 1052, in _send_output
    self.send(msg)
  File "/usr/lib/python3.11/http/client.py", line 990, in send
    self.connect()
  File "/usr/lib/python3.11/site-packages/urllib3/connection.py", line 205, in connect
    conn = self._new_conn()
           ^^^^^^^^^^^^^^^^
  File "/usr/lib/python3.11/site-packages/urllib3/connection.py", line 186, in _new_conn
    raise NewConnectionError(
urllib3.exceptions.NewConnectionError: <urllib3.connection.HTTPConnection object at 0x7ac343fa6990>: Failed to establish a new connection: [Errno 101] Network is unreachable

During handling of the above exception, another exception occurred:

Traceback (most recent call last):
  File "/usr/lib/python3.11/site-packages/requests/adapters.py", line 486, in send
    resp = conn.urlopen(
           ^^^^^^^^^^^^^
  File "/usr/lib/python3.11/site-packages/urllib3/connectionpool.py", line 799, in urlopen
    retries = retries.increment(
              ^^^^^^^^^^^^^^^^^^
  File "/usr/lib/python3.11/site-packages/urllib3/util/retry.py", line 592, in increment
    raise MaxRetryError(_pool, url, error or ResponseError(cause))
urllib3.exceptions.MaxRetryError: HTTPConnectionPool(host='tiny.cc', port=80): Max retries exceeded with url: /variety-options-063 (Caused by NewConnectionError('<urllib3.connection.HTTPConnection object at 0x7ac343fa6990>: Failed to establish a new connection: [Errno 101] Network is unreachable'))

During handling of the above exception, another exception occurred:

Traceback (most recent call last):
  File "/usr/lib/python3.11/site-packages/variety/VarietyWindow.py", line 1084, in server_options_thread
    self.server_options = Util.fetch_json(VarietyWindow.SERVERSIDE_OPTIONS_URL)
                          ^^^^^^^^^^^^^^^^^^^^^^^^^^^^^^^^^^^^^^^^^^^^^^^^^^^^^
  File "/usr/lib/python3.11/site-packages/variety/Util.py", line 684, in fetch_json
    return Util.request(url, data, **request_kwargs).json()
           ^^^^^^^^^^^^^^^^^^^^^^^^^^^^^^^^^^^^^^^^^
  File "/usr/lib/python3.11/site-packages/variety/Util.py", line 654, in request
    r = requests.request(
        ^^^^^^^^^^^^^^^^^
  File "/usr/lib/python3.11/site-packages/requests/api.py", line 59, in request
    return session.request(method=method, url=url, **kwargs)
           ^^^^^^^^^^^^^^^^^^^^^^^^^^^^^^^^^^^^^^^^^^^^^^^^^
  File "/usr/lib/python3.11/site-packages/requests/sessions.py", line 589, in request
    resp = self.send(prep, **send_kwargs)
           ^^^^^^^^^^^^^^^^^^^^^^^^^^^^^^
  File "/usr/lib/python3.11/site-packages/requests/sessions.py", line 703, in send
    r = adapter.send(request, **kwargs)
        ^^^^^^^^^^^^^^^^^^^^^^^^^^^^^^^
  File "/usr/lib/python3.11/site-packages/requests/adapters.py", line 519, in send
    raise ConnectionError(e, request=request)
requests.exceptions.ConnectionError: HTTPConnectionPool(host='tiny.cc', port=80): Max retries exceeded with url: /variety-options-063 (Caused by NewConnectionError('<urllib3.connection.HTTPConnection object at 0x7ac343fa6990>: Failed to establish a new connection: [Errno 101] Network is unreachable'))
INFO: 2024-03-11 18:59:32,246: server_options_thread() 'Fetching server options from http://tiny.cc/variety-options-063'
ERROR: 2024-03-11 18:59:37,263: server_options_thread() 'Could not fetch Variety serverside options'
Traceback (most recent call last):
  File "/usr/lib/python3.11/site-packages/urllib3/connection.py", line 174, in _new_conn
    conn = connection.create_connection(
           ^^^^^^^^^^^^^^^^^^^^^^^^^^^^^
  File "/usr/lib/python3.11/site-packages/urllib3/util/connection.py", line 95, in create_connection
    raise err
  File "/usr/lib/python3.11/site-packages/urllib3/util/connection.py", line 85, in create_connection
    sock.connect(sa)
OSError: [Errno 101] Network is unreachable

During handling of the above exception, another exception occurred:

Traceback (most recent call last):
  File "/usr/lib/python3.11/site-packages/urllib3/connectionpool.py", line 715, in urlopen
    httplib_response = self._make_request(
                       ^^^^^^^^^^^^^^^^^^^
  File "/usr/lib/python3.11/site-packages/urllib3/connectionpool.py", line 416, in _make_request
    conn.request(method, url, **httplib_request_kw)
  File "/usr/lib/python3.11/site-packages/urllib3/connection.py", line 244, in request
    super(HTTPConnection, self).request(method, url, body=body, headers=headers)
  File "/usr/lib/python3.11/http/client.py", line 1298, in request
    self._send_request(method, url, body, headers, encode_chunked)
  File "/usr/lib/python3.11/http/client.py", line 1344, in _send_request
    self.endheaders(body, encode_chunked=encode_chunked)
  File "/usr/lib/python3.11/http/client.py", line 1293, in endheaders
    self._send_output(message_body, encode_chunked=encode_chunked)
  File "/usr/lib/python3.11/http/client.py", line 1052, in _send_output
    self.send(msg)
  File "/usr/lib/python3.11/http/client.py", line 990, in send
    self.connect()
  File "/usr/lib/python3.11/site-packages/urllib3/connection.py", line 205, in connect
    conn = self._new_conn()
           ^^^^^^^^^^^^^^^^
  File "/usr/lib/python3.11/site-packages/urllib3/connection.py", line 186, in _new_conn
    raise NewConnectionError(
urllib3.exceptions.NewConnectionError: <urllib3.connection.HTTPConnection object at 0x7ac343f7e450>: Failed to establish a new connection: [Errno 101] Network is unreachable

During handling of the above exception, another exception occurred:

Traceback (most recent call last):
  File "/usr/lib/python3.11/site-packages/requests/adapters.py", line 486, in send
    resp = conn.urlopen(
           ^^^^^^^^^^^^^
  File "/usr/lib/python3.11/site-packages/urllib3/connectionpool.py", line 799, in urlopen
    retries = retries.increment(
              ^^^^^^^^^^^^^^^^^^
  File "/usr/lib/python3.11/site-packages/urllib3/util/retry.py", line 592, in increment
    raise MaxRetryError(_pool, url, error or ResponseError(cause))
urllib3.exceptions.MaxRetryError: HTTPConnectionPool(host='tiny.cc', port=80): Max retries exceeded with url: /variety-options-063 (Caused by NewConnectionError('<urllib3.connection.HTTPConnection object at 0x7ac343f7e450>: Failed to establish a new connection: [Errno 101] Network is unreachable'))

During handling of the above exception, another exception occurred:

Traceback (most recent call last):
  File "/usr/lib/python3.11/site-packages/variety/VarietyWindow.py", line 1084, in server_options_thread
    self.server_options = Util.fetch_json(VarietyWindow.SERVERSIDE_OPTIONS_URL)
                          ^^^^^^^^^^^^^^^^^^^^^^^^^^^^^^^^^^^^^^^^^^^^^^^^^^^^^
  File "/usr/lib/python3.11/site-packages/variety/Util.py", line 684, in fetch_json
    return Util.request(url, data, **request_kwargs).json()
           ^^^^^^^^^^^^^^^^^^^^^^^^^^^^^^^^^^^^^^^^^
  File "/usr/lib/python3.11/site-packages/variety/Util.py", line 654, in request
    r = requests.request(
        ^^^^^^^^^^^^^^^^^
  File "/usr/lib/python3.11/site-packages/requests/api.py", line 59, in request
    return session.request(method=method, url=url, **kwargs)
           ^^^^^^^^^^^^^^^^^^^^^^^^^^^^^^^^^^^^^^^^^^^^^^^^^
  File "/usr/lib/python3.11/site-packages/requests/sessions.py", line 589, in request
    resp = self.send(prep, **send_kwargs)
           ^^^^^^^^^^^^^^^^^^^^^^^^^^^^^^
  File "/usr/lib/python3.11/site-packages/requests/sessions.py", line 703, in send
    r = adapter.send(request, **kwargs)
        ^^^^^^^^^^^^^^^^^^^^^^^^^^^^^^^
  File "/usr/lib/python3.11/site-packages/requests/adapters.py", line 519, in send
    raise ConnectionError(e, request=request)
requests.exceptions.ConnectionError: HTTPConnectionPool(host='tiny.cc', port=80): Max retries exceeded with url: /variety-options-063 (Caused by NewConnectionError('<urllib3.connection.HTTPConnection object at 0x7ac343f7e450>: Failed to establish a new connection: [Errno 101] Network is unreachable'))
INFO: 2024-03-11 19:00:07,270: server_options_thread() 'Fetching server options from http://tiny.cc/variety-options-063'
ERROR: 2024-03-11 19:00:12,287: server_options_thread() 'Could not fetch Variety serverside options'
Traceback (most recent call last):
  File "/usr/lib/python3.11/site-packages/urllib3/connection.py", line 174, in _new_conn
    conn = connection.create_connection(
           ^^^^^^^^^^^^^^^^^^^^^^^^^^^^^
  File "/usr/lib/python3.11/site-packages/urllib3/util/connection.py", line 95, in create_connection
    raise err
  File "/usr/lib/python3.11/site-packages/urllib3/util/connection.py", line 85, in create_connection
    sock.connect(sa)
OSError: [Errno 101] Network is unreachable

During handling of the above exception, another exception occurred:

Traceback (most recent call last):
  File "/usr/lib/python3.11/site-packages/urllib3/connectionpool.py", line 715, in urlopen
    httplib_response = self._make_request(
                       ^^^^^^^^^^^^^^^^^^^
  File "/usr/lib/python3.11/site-packages/urllib3/connectionpool.py", line 416, in _make_request
    conn.request(method, url, **httplib_request_kw)
  File "/usr/lib/python3.11/site-packages/urllib3/connection.py", line 244, in request
    super(HTTPConnection, self).request(method, url, body=body, headers=headers)
  File "/usr/lib/python3.11/http/client.py", line 1298, in request
    self._send_request(method, url, body, headers, encode_chunked)
  File "/usr/lib/python3.11/http/client.py", line 1344, in _send_request
    self.endheaders(body, encode_chunked=encode_chunked)
  File "/usr/lib/python3.11/http/client.py", line 1293, in endheaders
    self._send_output(message_body, encode_chunked=encode_chunked)
  File "/usr/lib/python3.11/http/client.py", line 1052, in _send_output
    self.send(msg)
  File "/usr/lib/python3.11/http/client.py", line 990, in send
    self.connect()
  File "/usr/lib/python3.11/site-packages/urllib3/connection.py", line 205, in connect
    conn = self._new_conn()
           ^^^^^^^^^^^^^^^^
  File "/usr/lib/python3.11/site-packages/urllib3/connection.py", line 186, in _new_conn
    raise NewConnectionError(
urllib3.exceptions.NewConnectionError: <urllib3.connection.HTTPConnection object at 0x7ac343f7ce10>: Failed to establish a new connection: [Errno 101] Network is unreachable

During handling of the above exception, another exception occurred:

Traceback (most recent call last):
  File "/usr/lib/python3.11/site-packages/requests/adapters.py", line 486, in send
    resp = conn.urlopen(
           ^^^^^^^^^^^^^
  File "/usr/lib/python3.11/site-packages/urllib3/connectionpool.py", line 799, in urlopen
    retries = retries.increment(
              ^^^^^^^^^^^^^^^^^^
  File "/usr/lib/python3.11/site-packages/urllib3/util/retry.py", line 592, in increment
    raise MaxRetryError(_pool, url, error or ResponseError(cause))
urllib3.exceptions.MaxRetryError: HTTPConnectionPool(host='tiny.cc', port=80): Max retries exceeded with url: /variety-options-063 (Caused by NewConnectionError('<urllib3.connection.HTTPConnection object at 0x7ac343f7ce10>: Failed to establish a new connection: [Errno 101] Network is unreachable'))

During handling of the above exception, another exception occurred:

Traceback (most recent call last):
  File "/usr/lib/python3.11/site-packages/variety/VarietyWindow.py", line 1084, in server_options_thread
    self.server_options = Util.fetch_json(VarietyWindow.SERVERSIDE_OPTIONS_URL)
                          ^^^^^^^^^^^^^^^^^^^^^^^^^^^^^^^^^^^^^^^^^^^^^^^^^^^^^
  File "/usr/lib/python3.11/site-packages/variety/Util.py", line 684, in fetch_json
    return Util.request(url, data, **request_kwargs).json()
           ^^^^^^^^^^^^^^^^^^^^^^^^^^^^^^^^^^^^^^^^^
  File "/usr/lib/python3.11/site-packages/variety/Util.py", line 654, in request
    r = requests.request(
        ^^^^^^^^^^^^^^^^^
  File "/usr/lib/python3.11/site-packages/requests/api.py", line 59, in request
    return session.request(method=method, url=url, **kwargs)
           ^^^^^^^^^^^^^^^^^^^^^^^^^^^^^^^^^^^^^^^^^^^^^^^^^
  File "/usr/lib/python3.11/site-packages/requests/sessions.py", line 589, in request
    resp = self.send(prep, **send_kwargs)
           ^^^^^^^^^^^^^^^^^^^^^^^^^^^^^^
  File "/usr/lib/python3.11/site-packages/requests/sessions.py", line 703, in send
    r = adapter.send(request, **kwargs)
        ^^^^^^^^^^^^^^^^^^^^^^^^^^^^^^^
  File "/usr/lib/python3.11/site-packages/requests/adapters.py", line 519, in send
    raise ConnectionError(e, request=request)
requests.exceptions.ConnectionError: HTTPConnectionPool(host='tiny.cc', port=80): Max retries exceeded with url: /variety-options-063 (Caused by NewConnectionError('<urllib3.connection.HTTPConnection object at 0x7ac343f7ce10>: Failed to establish a new connection: [Errno 101] Network is unreachable'))
INFO: 2024-03-11 19:00:42,297: server_options_thread() 'Fetching server options from http://tiny.cc/variety-options-063'
ERROR: 2024-03-11 19:00:47,313: server_options_thread() 'Could not fetch Variety serverside options'
Traceback (most recent call last):
  File "/usr/lib/python3.11/site-packages/urllib3/connection.py", line 174, in _new_conn
    conn = connection.create_connection(
           ^^^^^^^^^^^^^^^^^^^^^^^^^^^^^
  File "/usr/lib/python3.11/site-packages/urllib3/util/connection.py", line 95, in create_connection
    raise err
  File "/usr/lib/python3.11/site-packages/urllib3/util/connection.py", line 85, in create_connection
    sock.connect(sa)
OSError: [Errno 101] Network is unreachable

During handling of the above exception, another exception occurred:

Traceback (most recent call last):
  File "/usr/lib/python3.11/site-packages/urllib3/connectionpool.py", line 715, in urlopen
    httplib_response = self._make_request(
                       ^^^^^^^^^^^^^^^^^^^
  File "/usr/lib/python3.11/site-packages/urllib3/connectionpool.py", line 416, in _make_request
    conn.request(method, url, **httplib_request_kw)
  File "/usr/lib/python3.11/site-packages/urllib3/connection.py", line 244, in request
    super(HTTPConnection, self).request(method, url, body=body, headers=headers)
  File "/usr/lib/python3.11/http/client.py", line 1298, in request
    self._send_request(method, url, body, headers, encode_chunked)
  File "/usr/lib/python3.11/http/client.py", line 1344, in _send_request
    self.endheaders(body, encode_chunked=encode_chunked)
  File "/usr/lib/python3.11/http/client.py", line 1293, in endheaders
    self._send_output(message_body, encode_chunked=encode_chunked)
  File "/usr/lib/python3.11/http/client.py", line 1052, in _send_output
    self.send(msg)
  File "/usr/lib/python3.11/http/client.py", line 990, in send
    self.connect()
  File "/usr/lib/python3.11/site-packages/urllib3/connection.py", line 205, in connect
    conn = self._new_conn()
           ^^^^^^^^^^^^^^^^
  File "/usr/lib/python3.11/site-packages/urllib3/connection.py", line 186, in _new_conn
    raise NewConnectionError(
urllib3.exceptions.NewConnectionError: <urllib3.connection.HTTPConnection object at 0x7ac343f7e990>: Failed to establish a new connection: [Errno 101] Network is unreachable

During handling of the above exception, another exception occurred:

Traceback (most recent call last):
  File "/usr/lib/python3.11/site-packages/requests/adapters.py", line 486, in send
    resp = conn.urlopen(
           ^^^^^^^^^^^^^
  File "/usr/lib/python3.11/site-packages/urllib3/connectionpool.py", line 799, in urlopen
    retries = retries.increment(
              ^^^^^^^^^^^^^^^^^^
  File "/usr/lib/python3.11/site-packages/urllib3/util/retry.py", line 592, in increment
    raise MaxRetryError(_pool, url, error or ResponseError(cause))
urllib3.exceptions.MaxRetryError: HTTPConnectionPool(host='tiny.cc', port=80): Max retries exceeded with url: /variety-options-063 (Caused by NewConnectionError('<urllib3.connection.HTTPConnection object at 0x7ac343f7e990>: Failed to establish a new connection: [Errno 101] Network is unreachable'))

During handling of the above exception, another exception occurred:

Traceback (most recent call last):
  File "/usr/lib/python3.11/site-packages/variety/VarietyWindow.py", line 1084, in server_options_thread
    self.server_options = Util.fetch_json(VarietyWindow.SERVERSIDE_OPTIONS_URL)
                          ^^^^^^^^^^^^^^^^^^^^^^^^^^^^^^^^^^^^^^^^^^^^^^^^^^^^^
  File "/usr/lib/python3.11/site-packages/variety/Util.py", line 684, in fetch_json
    return Util.request(url, data, **request_kwargs).json()
           ^^^^^^^^^^^^^^^^^^^^^^^^^^^^^^^^^^^^^^^^^
  File "/usr/lib/python3.11/site-packages/variety/Util.py", line 654, in request
    r = requests.request(
        ^^^^^^^^^^^^^^^^^
  File "/usr/lib/python3.11/site-packages/requests/api.py", line 59, in request
    return session.request(method=method, url=url, **kwargs)
           ^^^^^^^^^^^^^^^^^^^^^^^^^^^^^^^^^^^^^^^^^^^^^^^^^
  File "/usr/lib/python3.11/site-packages/requests/sessions.py", line 589, in request
    resp = self.send(prep, **send_kwargs)
           ^^^^^^^^^^^^^^^^^^^^^^^^^^^^^^
  File "/usr/lib/python3.11/site-packages/requests/sessions.py", line 703, in send
    r = adapter.send(request, **kwargs)
        ^^^^^^^^^^^^^^^^^^^^^^^^^^^^^^^
  File "/usr/lib/python3.11/site-packages/requests/adapters.py", line 519, in send
    raise ConnectionError(e, request=request)
requests.exceptions.ConnectionError: HTTPConnectionPool(host='tiny.cc', port=80): Max retries exceeded with url: /variety-options-063 (Caused by NewConnectionError('<urllib3.connection.HTTPConnection object at 0x7ac343f7e990>: Failed to establish a new connection: [Errno 101] Network is unreachable'))
INFO: 2024-03-11 19:01:17,320: server_options_thread() 'Fetching server options from http://tiny.cc/variety-options-063'
ERROR: 2024-03-11 19:01:22,340: server_options_thread() 'Could not fetch Variety serverside options'
Traceback (most recent call last):
  File "/usr/lib/python3.11/site-packages/urllib3/connection.py", line 174, in _new_conn
    conn = connection.create_connection(
           ^^^^^^^^^^^^^^^^^^^^^^^^^^^^^
  File "/usr/lib/python3.11/site-packages/urllib3/util/connection.py", line 95, in create_connection
    raise err
  File "/usr/lib/python3.11/site-packages/urllib3/util/connection.py", line 85, in create_connection
    sock.connect(sa)
OSError: [Errno 101] Network is unreachable

During handling of the above exception, another exception occurred:

Traceback (most recent call last):
  File "/usr/lib/python3.11/site-packages/urllib3/connectionpool.py", line 715, in urlopen
    httplib_response = self._make_request(
                       ^^^^^^^^^^^^^^^^^^^
  File "/usr/lib/python3.11/site-packages/urllib3/connectionpool.py", line 416, in _make_request
    conn.request(method, url, **httplib_request_kw)
  File "/usr/lib/python3.11/site-packages/urllib3/connection.py", line 244, in request
    super(HTTPConnection, self).request(method, url, body=body, headers=headers)
  File "/usr/lib/python3.11/http/client.py", line 1298, in request
    self._send_request(method, url, body, headers, encode_chunked)
  File "/usr/lib/python3.11/http/client.py", line 1344, in _send_request
    self.endheaders(body, encode_chunked=encode_chunked)
  File "/usr/lib/python3.11/http/client.py", line 1293, in endheaders
    self._send_output(message_body, encode_chunked=encode_chunked)
  File "/usr/lib/python3.11/http/client.py", line 1052, in _send_output
    self.send(msg)
  File "/usr/lib/python3.11/http/client.py", line 990, in send
    self.connect()
  File "/usr/lib/python3.11/site-packages/urllib3/connection.py", line 205, in connect
    conn = self._new_conn()
           ^^^^^^^^^^^^^^^^
  File "/usr/lib/python3.11/site-packages/urllib3/connection.py", line 186, in _new_conn
    raise NewConnectionError(
urllib3.exceptions.NewConnectionError: <urllib3.connection.HTTPConnection object at 0x7ac361058750>: Failed to establish a new connection: [Errno 101] Network is unreachable

During handling of the above exception, another exception occurred:

Traceback (most recent call last):
  File "/usr/lib/python3.11/site-packages/requests/adapters.py", line 486, in send
    resp = conn.urlopen(
           ^^^^^^^^^^^^^
  File "/usr/lib/python3.11/site-packages/urllib3/connectionpool.py", line 799, in urlopen
    retries = retries.increment(
              ^^^^^^^^^^^^^^^^^^
  File "/usr/lib/python3.11/site-packages/urllib3/util/retry.py", line 592, in increment
    raise MaxRetryError(_pool, url, error or ResponseError(cause))
urllib3.exceptions.MaxRetryError: HTTPConnectionPool(host='tiny.cc', port=80): Max retries exceeded with url: /variety-options-063 (Caused by NewConnectionError('<urllib3.connection.HTTPConnection object at 0x7ac361058750>: Failed to establish a new connection: [Errno 101] Network is unreachable'))

During handling of the above exception, another exception occurred:

Traceback (most recent call last):
  File "/usr/lib/python3.11/site-packages/variety/VarietyWindow.py", line 1084, in server_options_thread
    self.server_options = Util.fetch_json(VarietyWindow.SERVERSIDE_OPTIONS_URL)
                          ^^^^^^^^^^^^^^^^^^^^^^^^^^^^^^^^^^^^^^^^^^^^^^^^^^^^^
  File "/usr/lib/python3.11/site-packages/variety/Util.py", line 684, in fetch_json
    return Util.request(url, data, **request_kwargs).json()
           ^^^^^^^^^^^^^^^^^^^^^^^^^^^^^^^^^^^^^^^^^
  File "/usr/lib/python3.11/site-packages/variety/Util.py", line 654, in request
    r = requests.request(
        ^^^^^^^^^^^^^^^^^
  File "/usr/lib/python3.11/site-packages/requests/api.py", line 59, in request
    return session.request(method=method, url=url, **kwargs)
           ^^^^^^^^^^^^^^^^^^^^^^^^^^^^^^^^^^^^^^^^^^^^^^^^^
  File "/usr/lib/python3.11/site-packages/requests/sessions.py", line 589, in request
    resp = self.send(prep, **send_kwargs)
           ^^^^^^^^^^^^^^^^^^^^^^^^^^^^^^
  File "/usr/lib/python3.11/site-packages/requests/sessions.py", line 703, in send
    r = adapter.send(request, **kwargs)
        ^^^^^^^^^^^^^^^^^^^^^^^^^^^^^^^
  File "/usr/lib/python3.11/site-packages/requests/adapters.py", line 519, in send
    raise ConnectionError(e, request=request)
requests.exceptions.ConnectionError: HTTPConnectionPool(host='tiny.cc', port=80): Max retries exceeded with url: /variety-options-063 (Caused by NewConnectionError('<urllib3.connection.HTTPConnection object at 0x7ac361058750>: Failed to establish a new connection: [Errno 101] Network is unreachable'))
INFO: 2024-03-11 19:01:43,382: get_throttling() 'Flickr: parsing serverside options'
INFO: 2024-03-11 19:01:43,383: get_throttling() 'Could not parse Flickr serverside options, using defaults 120, 20'
INFO: 2024-03-11 19:01:43,383: get_throttling() 'Flickr: parsing serverside options'
INFO: 2024-03-11 19:01:43,383: get_throttling() 'Could not parse Flickr serverside options, using defaults 120, 20'
INFO: 2024-03-11 19:01:43,383: download_one() 'Flickr: Downloading an image, config: user:www.flickr.com/photos/peter-levi/;user_id:93647178@N00;'
INFO: 2024-03-11 19:01:43,383: download_one() 'Flickr: Queue size: 0'
INFO: 2024-03-11 19:01:43,383: get_throttling() 'Flickr: parsing serverside options'
INFO: 2024-03-11 19:01:43,383: get_throttling() 'Could not parse Flickr serverside options, using defaults 120, 20'
INFO: 2024-03-11 19:01:43,383: download_one() 'Flickr: Filling queue'
INFO: 2024-03-11 19:01:43,384: fetch() 'Making flickr API call: https://api.flickr.com/services/rest/?method=flickr.photos.search&api_key=0553a848c09bcfd21d3a984d9408c04e&per_page=500&tag_mode=all&format=json&nojsoncallback=1&user_id=93647178@N00'
ERROR: 2024-03-11 19:01:48,400: download_one_from() 'Could not download wallpaper:'
Traceback (most recent call last):
  File "/usr/lib/python3.11/site-packages/urllib3/connection.py", line 174, in _new_conn
    conn = connection.create_connection(
           ^^^^^^^^^^^^^^^^^^^^^^^^^^^^^
  File "/usr/lib/python3.11/site-packages/urllib3/util/connection.py", line 95, in create_connection
    raise err
  File "/usr/lib/python3.11/site-packages/urllib3/util/connection.py", line 85, in create_connection
    sock.connect(sa)
OSError: [Errno 101] Network is unreachable

During handling of the above exception, another exception occurred:

Traceback (most recent call last):
  File "/usr/lib/python3.11/site-packages/urllib3/connectionpool.py", line 715, in urlopen
    httplib_response = self._make_request(
                       ^^^^^^^^^^^^^^^^^^^
  File "/usr/lib/python3.11/site-packages/urllib3/connectionpool.py", line 404, in _make_request
    self._validate_conn(conn)
  File "/usr/lib/python3.11/site-packages/urllib3/connectionpool.py", line 1058, in _validate_conn
    conn.connect()
  File "/usr/lib/python3.11/site-packages/urllib3/connection.py", line 363, in connect
    self.sock = conn = self._new_conn()
                       ^^^^^^^^^^^^^^^^
  File "/usr/lib/python3.11/site-packages/urllib3/connection.py", line 186, in _new_conn
    raise NewConnectionError(
urllib3.exceptions.NewConnectionError: <urllib3.connection.HTTPSConnection object at 0x7ac343fa6710>: Failed to establish a new connection: [Errno 101] Network is unreachable

During handling of the above exception, another exception occurred:

Traceback (most recent call last):
  File "/usr/lib/python3.11/site-packages/requests/adapters.py", line 486, in send
    resp = conn.urlopen(
           ^^^^^^^^^^^^^
  File "/usr/lib/python3.11/site-packages/urllib3/connectionpool.py", line 799, in urlopen
    retries = retries.increment(
              ^^^^^^^^^^^^^^^^^^
  File "/usr/lib/python3.11/site-packages/urllib3/util/retry.py", line 592, in increment
    raise MaxRetryError(_pool, url, error or ResponseError(cause))
urllib3.exceptions.MaxRetryError: HTTPSConnectionPool(host='api.flickr.com', port=443): Max retries exceeded with url: /services/rest/?method=flickr.photos.search&api_key=0553a848c09bcfd21d3a984d9408c04e&per_page=500&tag_mode=all&format=json&nojsoncallback=1&user_id=93647178@N00 (Caused by NewConnectionError('<urllib3.connection.HTTPSConnection object at 0x7ac343fa6710>: Failed to establish a new connection: [Errno 101] Network is unreachable'))

During handling of the above exception, another exception occurred:

Traceback (most recent call last):
  File "/usr/lib/python3.11/site-packages/variety/VarietyWindow.py", line 1164, in download_one_from
    file = downloader.download_one()
           ^^^^^^^^^^^^^^^^^^^^^^^^^
  File "/usr/lib/python3.11/site-packages/variety/plugins/downloaders/DefaultDownloader.py", line 141, in download_one
    items = self.fill_queue()
            ^^^^^^^^^^^^^^^^^
  File "/usr/lib/python3.11/site-packages/variety/FlickrDownloader.py", line 161, in fill_queue
    resp = FlickrDownloader.fetch(call)
           ^^^^^^^^^^^^^^^^^^^^^^^^^^^^
  File "/usr/lib/python3.11/site-packages/variety/FlickrDownloader.py", line 74, in fetch
    return Util.fetch_json(call)
           ^^^^^^^^^^^^^^^^^^^^^
  File "/usr/lib/python3.11/site-packages/variety/Util.py", line 684, in fetch_json
    return Util.request(url, data, **request_kwargs).json()
           ^^^^^^^^^^^^^^^^^^^^^^^^^^^^^^^^^^^^^^^^^
  File "/usr/lib/python3.11/site-packages/variety/Util.py", line 654, in request
    r = requests.request(
        ^^^^^^^^^^^^^^^^^
  File "/usr/lib/python3.11/site-packages/requests/api.py", line 59, in request
    return session.request(method=method, url=url, **kwargs)
           ^^^^^^^^^^^^^^^^^^^^^^^^^^^^^^^^^^^^^^^^^^^^^^^^^
  File "/usr/lib/python3.11/site-packages/requests/sessions.py", line 589, in request
    resp = self.send(prep, **send_kwargs)
           ^^^^^^^^^^^^^^^^^^^^^^^^^^^^^^
  File "/usr/lib/python3.11/site-packages/requests/sessions.py", line 703, in send
    r = adapter.send(request, **kwargs)
        ^^^^^^^^^^^^^^^^^^^^^^^^^^^^^^^
  File "/usr/lib/python3.11/site-packages/requests/adapters.py", line 519, in send
    raise ConnectionError(e, request=request)
requests.exceptions.ConnectionError: HTTPSConnectionPool(host='api.flickr.com', port=443): Max retries exceeded with url: /services/rest/?method=flickr.photos.search&api_key=0553a848c09bcfd21d3a984d9408c04e&per_page=500&tag_mode=all&format=json&nojsoncallback=1&user_id=93647178@N00 (Caused by NewConnectionError('<urllib3.connection.HTTPSConnection object at 0x7ac343fa6710>: Failed to establish a new connection: [Errno 101] Network is unreachable'))
INFO: 2024-03-11 19:03:37,214: regular_change_thread() 'regular_change changes wallpaper'
INFO: 2024-03-11 19:03:37,214: set_wallpaper() 'Calling set_wallpaper with /usr/share/backgrounds/sway/Sway_Wallpaper_Blue_768x1024.png'
INFO: 2024-03-11 19:03:37,215: do_set_wp() 'Calling do_set_wp with /usr/share/backgrounds/sway/Sway_Wallpaper_Blue_768x1024.png, time: 1710155017.215595'
INFO: 2024-03-11 19:03:37,216: prepare_thread() 'Prepared buffer contains 4 images'
INFO: 2024-03-11 19:03:37,216: prepare_thread() 'Preparing some images'
INFO: 2024-03-11 19:03:37,237: prepare_thread() 'After search prepared buffer contains 5 images'
INFO: 2024-03-11 19:03:37,247: update_indicator() 'Setting file info to: /usr/share/backgrounds/sway/Sway_Wallpaper_Blue_768x1024.png'
INFO: 2024-03-11 19:03:39,238: trigger_download() 'Triggering download thread to check if download needed and possible'
INFO: 2024-03-11 19:03:39,239: get_throttling() 'Flickr: parsing serverside options'
INFO: 2024-03-11 19:03:39,239: get_throttling() 'Could not parse Flickr serverside options, using defaults 120, 20'
INFO: 2024-03-11 19:03:39,239: get_throttling() 'Flickr: parsing serverside options'
INFO: 2024-03-11 19:03:39,239: get_throttling() 'Could not parse Flickr serverside options, using defaults 120, 20'
INFO: 2024-03-11 19:03:39,239: download_one() 'Flickr: Downloading an image, config: user:www.flickr.com/photos/peter-levi/;user_id:93647178@N00;'
INFO: 2024-03-11 19:03:39,240: download_one() 'Flickr: Queue size: 0'
INFO: 2024-03-11 19:03:39,240: get_throttling() 'Flickr: parsing serverside options'
INFO: 2024-03-11 19:03:39,240: get_throttling() 'Could not parse Flickr serverside options, using defaults 120, 20'
INFO: 2024-03-11 19:03:39,240: download_one() 'Flickr: Filling queue'
INFO: 2024-03-11 19:03:39,240: fetch() 'Making flickr API call: https://api.flickr.com/services/rest/?method=flickr.photos.search&api_key=0553a848c09bcfd21d3a984d9408c04e&per_page=500&tag_mode=all&format=json&nojsoncallback=1&user_id=93647178@N00'
ERROR: 2024-03-11 19:03:44,259: download_one_from() 'Could not download wallpaper:'
Traceback (most recent call last):
  File "/usr/lib/python3.11/site-packages/urllib3/connection.py", line 174, in _new_conn
    conn = connection.create_connection(
           ^^^^^^^^^^^^^^^^^^^^^^^^^^^^^
  File "/usr/lib/python3.11/site-packages/urllib3/util/connection.py", line 95, in create_connection
    raise err
  File "/usr/lib/python3.11/site-packages/urllib3/util/connection.py", line 85, in create_connection
    sock.connect(sa)
OSError: [Errno 101] Network is unreachable

During handling of the above exception, another exception occurred:

Traceback (most recent call last):
  File "/usr/lib/python3.11/site-packages/urllib3/connectionpool.py", line 715, in urlopen
    httplib_response = self._make_request(
                       ^^^^^^^^^^^^^^^^^^^
  File "/usr/lib/python3.11/site-packages/urllib3/connectionpool.py", line 404, in _make_request
    self._validate_conn(conn)
  File "/usr/lib/python3.11/site-packages/urllib3/connectionpool.py", line 1058, in _validate_conn
    conn.connect()
  File "/usr/lib/python3.11/site-packages/urllib3/connection.py", line 363, in connect
    self.sock = conn = self._new_conn()
                       ^^^^^^^^^^^^^^^^
  File "/usr/lib/python3.11/site-packages/urllib3/connection.py", line 186, in _new_conn
    raise NewConnectionError(
urllib3.exceptions.NewConnectionError: <urllib3.connection.HTTPSConnection object at 0x7ac343f56090>: Failed to establish a new connection: [Errno 101] Network is unreachable

During handling of the above exception, another exception occurred:

Traceback (most recent call last):
  File "/usr/lib/python3.11/site-packages/requests/adapters.py", line 486, in send
    resp = conn.urlopen(
           ^^^^^^^^^^^^^
  File "/usr/lib/python3.11/site-packages/urllib3/connectionpool.py", line 799, in urlopen
    retries = retries.increment(
              ^^^^^^^^^^^^^^^^^^
  File "/usr/lib/python3.11/site-packages/urllib3/util/retry.py", line 592, in increment
    raise MaxRetryError(_pool, url, error or ResponseError(cause))
urllib3.exceptions.MaxRetryError: HTTPSConnectionPool(host='api.flickr.com', port=443): Max retries exceeded with url: /services/rest/?method=flickr.photos.search&api_key=0553a848c09bcfd21d3a984d9408c04e&per_page=500&tag_mode=all&format=json&nojsoncallback=1&user_id=93647178@N00 (Caused by NewConnectionError('<urllib3.connection.HTTPSConnection object at 0x7ac343f56090>: Failed to establish a new connection: [Errno 101] Network is unreachable'))

During handling of the above exception, another exception occurred:

Traceback (most recent call last):
  File "/usr/lib/python3.11/site-packages/variety/VarietyWindow.py", line 1164, in download_one_from
    file = downloader.download_one()
           ^^^^^^^^^^^^^^^^^^^^^^^^^
  File "/usr/lib/python3.11/site-packages/variety/plugins/downloaders/DefaultDownloader.py", line 141, in download_one
    items = self.fill_queue()
            ^^^^^^^^^^^^^^^^^
  File "/usr/lib/python3.11/site-packages/variety/FlickrDownloader.py", line 161, in fill_queue
    resp = FlickrDownloader.fetch(call)
           ^^^^^^^^^^^^^^^^^^^^^^^^^^^^
  File "/usr/lib/python3.11/site-packages/variety/FlickrDownloader.py", line 74, in fetch
    return Util.fetch_json(call)
           ^^^^^^^^^^^^^^^^^^^^^
  File "/usr/lib/python3.11/site-packages/variety/Util.py", line 684, in fetch_json
    return Util.request(url, data, **request_kwargs).json()
           ^^^^^^^^^^^^^^^^^^^^^^^^^^^^^^^^^^^^^^^^^
  File "/usr/lib/python3.11/site-packages/variety/Util.py", line 654, in request
    r = requests.request(
        ^^^^^^^^^^^^^^^^^
  File "/usr/lib/python3.11/site-packages/requests/api.py", line 59, in request
    return session.request(method=method, url=url, **kwargs)
           ^^^^^^^^^^^^^^^^^^^^^^^^^^^^^^^^^^^^^^^^^^^^^^^^^
  File "/usr/lib/python3.11/site-packages/requests/sessions.py", line 589, in request
    resp = self.send(prep, **send_kwargs)
           ^^^^^^^^^^^^^^^^^^^^^^^^^^^^^^
  File "/usr/lib/python3.11/site-packages/requests/sessions.py", line 703, in send
    r = adapter.send(request, **kwargs)
        ^^^^^^^^^^^^^^^^^^^^^^^^^^^^^^^
  File "/usr/lib/python3.11/site-packages/requests/adapters.py", line 519, in send
    raise ConnectionError(e, request=request)
requests.exceptions.ConnectionError: HTTPSConnectionPool(host='api.flickr.com', port=443): Max retries exceeded with url: /services/rest/?method=flickr.photos.search&api_key=0553a848c09bcfd21d3a984d9408c04e&per_page=500&tag_mode=all&format=json&nojsoncallback=1&user_id=93647178@N00 (Caused by NewConnectionError('<urllib3.connection.HTTPSConnection object at 0x7ac343f56090>: Failed to establish a new connection: [Errno 101] Network is unreachable'))
